Workbook

Sheet Model
A1: Spares Sizing Model - component-level spares for drives, PSUs, optics, GPUs
A2: Legend: blue text on yellow = input you can change | black = formula | green = link from another sheet. Change inputs only in yellow cells (rows 6-13, and the blocks in column I).
A4: INPUTS
A5: Part class | B5: Drives (HDD) | C5: PSUs | D5: Optics (transceivers) | E5: GPUs (H100) | F5: Total | H5: OPTICS PRICE SCENARIO
A6: Fleet size (installed units; GPUs = modules or boards per I17) | B6: 500 | C6: 400 | D6: 1000 | E6: =IF($I$17="Board",$I$16/$I$18,$I$16) -> 1024 | H6: Selected price (Generic / Branded) | I6: Generic
A7: Annual failure rate (AFR) | B7: 0.0136 | C7: =1-EXP(-$B$13/C11) -> 0.017367417 | D7: 0.02 | E7: =IF($I$17="Board",1-(1-$I$24)^$I$18,$I$24) -> 0.090761538 | H7: Generic 800G OSFP 2xDR4 ($) | I7: 919
A8: Replenishment lead time (weeks) | B8: 12 | C8: 8 | D8: 16 | E8: 8 | H8: Branded-equivalent 800G OSFP 2xDR4, MSRP ($) | I8: 4141.54
A9: Target fill rate (service level) | B9: 0.95 | C9: 0.95 | D9: 0.95 | E9: 0.95 | H9: Optics unit cost (D10) follows I6. Sources on Assumptions tab.
A10: Unit cost ($) | B10: 1079.99 | C10: 531.16 | D10: =IF($I$6="Branded",$I$8,$I$7) -> 919 | E10: =IF($I$17="Board",$I$19,$I$19/$I$18) -> 22375
A11: Datasheet MTBF (hours) - PSUs only, converts to AFR | B11: n/a | C11: 500000 | D11: n/a | E11: n/a | H11: AFR sources - Drives: Backblaze 2025 | PSUs: formula AFR = 1 - e^(-8760/MTBF) from row 11 | Optics: assumption | GPUs: derived from Meta Llama 3 (I20-I24)
A12: Weeks per year (constant) | B12: 52 | H12: Fill rate = P(lead-time demand <= S-1): chance a failure finds a spare on the shelf. Drives the stock level. See Notes.
A13: Hours per year (constant) | B13: 8760 | H13: All input values are labeled on the Assumptions tab (status + source).
A14: OUTPUTS - POISSON (primary method)
A15: Expected failures per year | B15: =B6*B7 -> 6.8 | C15: =C6*C7 -> 6.9469669 | D15: =D6*D7 -> 20 | E15: =E6*E7 -> 92.939815 | F15: =SUM(B15:E15) -> 126.68678 | H15: GPU INPUTS (NVIDIA H100 SXM)
A16: Expected demand during lead time (lambda) | B16: =B15*B8/$B$12 -> 1.5692308 | C16: =C15*C8/$B$12 -> 1.0687641 | D16: =D15*D8/$B$12 -> 6.1538462 | E16: =E15*E8/$B$12 -> 14.298433 | F16: =SUM(B16:E16) -> 23.090274 | H16: GPUs installed | I16: 1024
A17: Recommended stock level S (Poisson, meets fill-rate target) | B17: =COUNTIF(Poisson_Table!B$4:B$204,"<"&B9)+1 -> 5 | C17: =COUNTIF(Poisson_Table!C$4:C$204,"<"&C9)+1 -> 4 | D17: =COUNTIF(Poisson_Table!D$4:D$204,"<"&D9)+1 -> 11 | E17: =COUNTIF(Poisson_Table!E$4:E$204,"<"&E9)+1 -> 22 | H17: Sparing unit (Module / Board) | I17: Module
A18: Reorder point (one-for-one: reorder at every failure) = S - 1 | B18: =MAX(0,B17-1) -> 4 | C18: =MAX(0,C17-1) -> 3 | D18: =MAX(0,D17-1) -> 10 | E18: =MAX(0,E17-1) -> 21 | H18: GPUs per HGX board | I18: 8
A19: Safety stock = S - lambda | B19: =B17-B16 -> 3.4307692 | C19: =C17-C16 -> 2.9312359 | D19: =D17-D16 -> 4.8461538 | E19: =E17-E16 -> 7.701567 | F19: =SUM(B19:E19) -> 18.909726 | H19: HGX H100 8-GPU board price, new ($) | I19: 179000
A20: Capital tied up in spares ($) | B20: =B17*B10 -> 5399.95 | C20: =C17*C10 -> 2124.64 | D20: =D17*D10 -> 10109 | E20: =E17*E10 -> 492250 | F20: =SUM(B20:E20) -> 509883.59 | H20: Meta Llama 3 run: faulty-GPU interruptions | I20: 148
A21: Achieved fill rate = P(D <= S-1) [TARGET METRIC] | B21: =POISSON(B17-1,B16,TRUE()) -> 0.97797511 | C21: =POISSON(C17-1,C16,TRUE()) -> 0.97650268 | D21: =POISSON(D17-1,D16,TRUE()) -> 0.95069488 | E21: =POISSON(E17-1,E16,TRUE()) -> 0.96503011 | H21: Meta Llama 3 run: GPU HBM3 interruptions | I21: 72
A22: Cycle service level (no stockout in one lead time) = P(D <= S) | B22: =POISSON(B17,B16,TRUE()) -> 0.99448501 | C22: =POISSON(C17,C16,TRUE()) -> 0.99517326 | D22: =POISSON(D17,D16,TRUE()) -> 0.97621459 | E22: =POISSON(E17,E16,TRUE()) -> 0.979347 | H22: Meta Llama 3 run: cluster size (H100 GPUs) | I22: 16384
A23: Lookup table range check | B23: =IF(Poisson_Table!B$204<B9,"EXTEND TABLE","OK") -> OK | C23: =IF(Poisson_Table!C$204<C9,"EXTEND TABLE","OK") -> OK | D23: =IF(Poisson_Table!D$204<D9,"EXTEND TABLE","OK") -> OK | E23: =IF(Poisson_Table!E$204<E9,"EXTEND TABLE","OK") -> OK | H23: Meta Llama 3 run: length (days) | I23: 54
H24: Derived per-GPU AFR (annualized) = (I20+I21)/I22 x 365/I23 | I24: =(I20+I21)/I22*365/I23 -> 0.090761538
A25: OUTPUTS - NORMAL APPROXIMATION (comparison only) | H25: Module = spare single SXM GPUs (unit cost = board price / 8). Board = spare whole HGX boards; one GPU failure takes the board out, so board AFR = 1-(1-AFR)^8.
A26: z-score for target | B26: =NORMSINV(B9) -> 1.6448536 | C26: =NORMSINV(C9) -> 1.6448536 | D26: =NORMSINV(D9) -> 1.6448536 | E26: =NORMSINV(E9) -> 1.6448536 | H26: The 9.1% is an INTERRUPTION rate - likely an upper bound for physical replacements (some faults clear with a reset).
A27: Stock level S (normal: S-1 covers lambda + z x sqrt(lambda)) | B27: =MAX(1,ROUNDUP(B16+B26*SQRT(B16),0)+1) -> 5 | C27: =MAX(1,ROUNDUP(C16+C26*SQRT(C16),0)+1) -> 4 | D27: =MAX(1,ROUNDUP(D16+D26*SQRT(D16),0)+1) -> 12 | E27: =MAX(1,ROUNDUP(E16+E26*SQRT(E16),0)+1) -> 22
A28: Safety stock = S - lambda | B28: =B27-B16 -> 3.4307692 | C28: =C27-C16 -> 2.9312359 | D28: =D27-D16 -> 5.8461538 | E28: =E27-E16 -> 7.701567 | F28: =SUM(B28:E28) -> 19.909726
A29: Capital tied up in spares ($) | B29: =B27*B10 -> 5399.95 | C29: =C27*C10 -> 2124.64 | D29: =D27*D10 -> 11028 | E29: =E27*E10 -> 492250 | F29: =SUM(B29:E29) -> 510802.59
A30: True fill rate P(D <= S-1) if you stocked the normal S | B30: =POISSON(B27-1,B16,TRUE()) -> 0.97797511 | C30: =POISSON(C27-1,C16,TRUE()) -> 0.97650268 | D30: =POISSON(D27-1,D16,TRUE()) -> 0.97621459 | E30: =POISSON(E27-1,E16,TRUE()) -> 0.96503011
A32: POISSON vs NORMAL
A33: Difference in units (Poisson S - Normal S) | B33: =B17-B27 -> 0 | C33: =C17-C27 -> 0 | D33: =D17-D27 -> -1 | E33: =E17-E27 -> 0 | F33: =SUM(B33:E33) -> -1
A34: Difference in capital ($) | B34: =B20-B29 -> 0 | C34: =C20-C29 -> 0 | D34: =D20-D29 -> -919 | E34: =E20-E29 -> 0 | F34: =SUM(B34:E34) -> -919
A35: Normal approx under-covers target? | B35: =IF(B30<B9,"YES - normal understocks","No") -> No | C35: =IF(C30<C9,"YES - normal understocks","No") -> No | D35: =IF(D30<D9,"YES - normal understocks","No") -> No | E35: =IF(E30<E9,"YES - normal understocks","No") -> No
A37: OPTICS PRICE SCENARIO - SIDE BY SIDE (stock level from Poisson, column D)
A38: Metric | B38: Generic | C38: Branded-equivalent | D38: Difference (Branded - Generic)
A39: Optics unit price ($) | B39: =$I$7 -> 919 | C39: =$I$8 -> 4141.54 | D39: =C39-B39 -> 3222.54
A40: Optics spares capital = S x price ($) | B40: =$D$17*B39 -> 10109 | C40: =$D$17*C39 -> 45556.94 | D40: =C40-B40 -> 35447.94
A41: Drive + optics spares capital ($) | B41: =$B$20+B40 -> 15508.95 | C41: =$B$20+C40 -> 50956.89 | D41: =C41-B41 -> 35447.94
A42: Total spares capital, all 4 classes ($) | B42: =$B$20+$C$20+$E$20+B40 -> 509883.59 | C42: =$B$20+$C$20+$E$20+C40 -> 545331.53 | D42: =C42-B42 -> 35447.94
A44: OPTICS AFR SENSITIVITY (fleet, lead time, fill-rate target from column D)
...

Sheet Notes
A1: How to use
A2: 1. Edit only yellow cells on Model (rows 6-13). Everything else recalculates.
A3: 2. The Poisson block is the answer. The normal block shows why Poisson is used.
A4: 3. Check tab should read ALL PASS. If Model says EXTEND TABLE, lambda is too large for the 0-200 lookup.
A6: Method
A7: Expected failures/yr = fleet x AFR. Lead-time demand lambda = failures/yr x lead time / 52.
A8: Lead-time demand is modeled as Poisson(lambda): failures are rare, independent, and arrive one at a time.
A9: Policy: one-for-one (S-1, S) base stock - every failure triggers one replacement order.
A10: Normal approximation: S - 1 = ROUNDUP(lambda + z x sqrt(lambda)). Assumes a symmetric bell curve, which breaks down at small lambda.
A12: Target metric - fill rate (decision 2026-09-24)
A13: Fill rate = P(D <= S-1): the chance a failure finds a spare on the shelf. It sets the recommended stock level.
A14: Stock level S = smallest S with P(D <= S-1) >= target. Excel has no inverse Poisson, so Poisson_Table lists the CDF for k = 0-200; COUNTIF counts k values below target, which equals S-1.
... A30: No repair/RMA loop, no multi-site pooling. GPU board-level sparing is shown as a comparison, not as full node-level sparing.

Sheet Poisson_Table
A1: Cumulative Poisson P(lead-time demand <= k), lambda pulled from Model row 16
A2: Helper sheet - do not edit. S - 1 = count of k values whose CDF is still below the fill-rate target, so S = that count + 1.
A3: k | B3: Drives | C3: PSUs | D3: Optics | E3: GPUs (selected unit) | H3: Optics AFR sens. 1 | I3: Optics AFR sens. 2 | J3: Optics AFR sens. 3 | K3: GPU module 2% | L3: GPU module 5% | M3: GPU module base | N3: GPU board 2% | O3: GPU board 5% | P3: GPU board base
A4: 0 | B4: =POISSON($A4,Model!B$16,TRUE()) -> 0.20820528 | C4: =POISSON($A4,Model!C$16,TRUE()) -> 0.34343269 | D4: =POISSON($A4,Model!D$16,TRUE()) -> 0.0021252918 | E4: =POISSON($A4,Model!E$16,TRUE()) -> 6.1697764e-07 | H4: =POISSON($A4,Model!$C$46,TRUE()) -> 0.046100888 | I4: =POISSON($A4,Model!$C$47,TRUE()) -> 0.0021252918 | J4: =POISSON($A4,Model!$C$48,TRUE()) -> 4.5168654e-06 | K4: =POISSON($A4,Model!$C$53,TRUE()) -> 0.042819176 | L4: =POISSON($A4,Model!$C$54,TRUE()) -> 0.00037939864 | M4: =POISSON($A4,Model!$C$55,TRUE()) -> 6.1697764e-07 | N4: =POISSON($A4,Model!$G$53,TRUE()) -> 0.052928122 | O4: =POISSON($A4,Model!$G$54,TRUE()) -> 0.0013227684 | P4: =POISSON($A4,Model!$G$55,TRUE()) -> 2.770866e-05
A5: 1 | B5: =POISSON($A5,Model!B$16,TRUE()) -> 0.53492741 | C5: =POISSON($A5,Model!C$16,TRUE()) -> 0.71048124 | D5: =POISSON($A5,Model!D$16,TRUE()) -> 0.015204011 | E5: =POISSON($A5,Model!E$16,TRUE()) -> 9.4387912e-06 | H5: =POISSON($A5,Model!$C$46,TRUE()) -> 0.18794977 | I5: =POISSON($A5,Model!$C$47,TRUE()) -> 0.015204011 | J5: =POISSON($A5,Model!$C$48,TRUE()) -> 6.0109054e-05 | K5: =POISSON($A5,Model!$C$53,TRUE()) -> 0.17773252 | L5: =POISSON($A5,Model!$C$54,TRUE()) -> 0.0033678926 | M5: =POISSON($A5,Model!$C$55,TRUE()) -> 9.4387912e-06 | N5: =POISSON($A5,Model!$G$53,TRUE()) -> 0.20847437 | O5: =POISSON($A5,Model!$G$54,TRUE()) -> 0.010090115 | P5: =POISSON($A5,Model!$G$55,TRUE()) -> 0.00031847685
A6: 2 | B6: =POISSON($A6,Model!B$16,TRUE()) -> 0.79127862 | C6: =POISSON($A6,Model!C$16,TRUE()) -> 0.9066254 | D6: =POISSON($A6,Model!D$16,TRUE()) -> 0.055446223 | E6: =POISSON($A6,Model!E$16,TRUE()) -> 7.2507846e-05 | H6: =POISSON($A6,Model!$C$46,TRUE()) -> 0.40617883 | I6: =POISSON($A6,Model!$C$47,TRUE()) -> 0.055446223 | J6: =POISSON($A6,Model!$C$48,TRUE()) -> 0.00040221483 | K6: =POISSON($A6,Model!$C$53,TRUE()) -> 0.39027293 | L6: =POISSON($A6,Model!$C$54,TRUE()) -> 0.015137961 | M6: =POISSON($A6,Model!$C$55,TRUE()) -> 7.2507846e-05 | N6: =POISSON($A6,Model!$G$53,TRUE()) -> 0.43703562 | O6: =POISSON($A6,Model!$G$54,TRUE()) -> 0.039145227 | P6: =POISSON($A6,Model!$G$55,TRUE()) -> 0.0018441034
A7: 3 | B7: =POISSON($A7,Model!B$16,TRUE()) -> 0.92537002 | C7: =POISSON($A7,Model!C$16,TRUE()) -> 0.97650268 | D7: =POISSON($A7,Model!D$16,TRUE()) -> 0.13799435 | E7: =POISSON($A7,Model!E$16,TRUE()) -> 0.00037310407 | H7: =POISSON($A7,Model!$C$46,TRUE()) -> 0.6300035 | I7: =POISSON($A7,Model!$C$47,TRUE()) -> 0.13799435 | J7: =POISSON($A7,Model!$C$48,TRUE()) -> 0.0018057257 | K7: =POISSON($A7,Model!$C$53,TRUE()) -> 0.61349485 | L7: =POISSON($A7,Model!$C$54,TRUE()) -> 0.046041935 | M7: =POISSON($A7,Model!$C$55,TRUE()) -> 0.00037310407 | N7: =POISSON($A7,Model!$G$53,TRUE()) -> 0.66093578 | O7: =POISSON($A7,Model!$G$54,TRUE()) -> 0.10333793 | P7: =POISSON($A7,Model!$G$55,TRUE()) -> 0.007180626
A8: 4 | B8: =POISSON($A8,Model!B$16,TRUE()) -> 0.97797511 | C8: =POISSON($A8,Model!C$16,TRUE()) -> 0.99517326 | D8: =POISSON($A8,Model!D$16,TRUE()) -> 0.26499147 | E8: =POISSON($A8,Model!E$16,TRUE()) -> 0.0014476178 | H8: =POISSON($A8,Model!$C$46,TRUE()) -> 0.80217632 | I8: =POISSON($A8,Model!$C$47,TRUE()) -> 0.26499147 | J8: =POISSON($A8,Model!$C$48,TRUE()) -> 0.0061242208 | K8: =POISSON($A8,Model!$C$53,TRUE()) -> 0.78932504 | L8: =POISSON($A8,Model!$C$54,TRUE()) -> 0.10689899 | M8: =POISSON($A8,Model!$C$55,TRUE()) -> 0.0014476178 | N8: =POISSON($A8,Model!$G$53,TRUE()) -> 0.82543637 | O8: =POISSON($A8,Model!$G$54,TRUE()) -> 0.2097057 | P8: =POISSON($A8,Model!$G$55,TRUE()) -> 0.02118068
A9: 5 | B9: =POISSON($A9,Model!B$16,TRUE()) -> 0.99448501 | C9: =POISSON($A9,Model!C$16,TRUE()) -> 0.99916415 | D9: =POISSON($A9,Model!D$16,TRUE()) -> 0.42129562 | E9: =POISSON($A9,Model!E$16,TRUE()) -> 0.0045203903 | H9: =POISSON($A9,Model!$C$46,TRUE()) -> 0.90812883 | I9: =POISSON($A9,Model!$C$47,TRUE()) -> 0.42129562 | J9: =POISSON($A9,Model!$C$48,TRUE()) -> 0.016754362 | K9: =POISSON($A9,Model!$C$53,TRUE()) -> 0.90012511 | L9: =POISSON($A9,Model!$C$54,TRUE()) -> 0.20277226 | M9: =POISSON($A9,Model!$C$55,TRUE()) -> 0.0045203903 | N9: =POISSON($A9,Model!$G$53,TRUE()) -> 0.92212392 | O9: =POISSON($A9,Model!$G$54,TRUE()) -> 0.35070741 | P9: =POISSON($A9,Model!$G$55,TRUE()) -> 0.050563337
A10: 6 | B10: =POISSON($A10,Model!B$16,TRUE()) -> 0.99880299 | C10: =POISSON($A10,Model!C$16,TRUE()) -> 0.99987504 | D10: =POISSON($A10,Model!D$16,TRUE()) -> 0.58160756 | E10: =POISSON($A10,Model!E$16,TRUE()) -> 0.011843029 | H10: =POISSON($A10,Model!$C$46,TRUE()) -> 0.96246344 | I10: =POISSON($A10,Model!$C$47,TRUE()) -> 0.58160756 | J10: =POISSON($A10,Model!$C$48,TRUE()) -> 0.038559781 | K10: =POISSON($A10,Model!$C$53,TRUE()) -> 0.95830936 | L10: =POISSON($A10,Model!$C$54,TRUE()) -> 0.32863666 | M10: =POISSON($A10,Model!$C$55,TRUE()) -> 0.011843029 | N10: =POISSON($A10,Model!$G$53,TRUE()) -> 0.96948181 | O10: =POISSON($A10,Model!$G$54,TRUE()) -> 0.50646797 | P10: =POISSON($A10,Model!$G$55,TRUE()) -> 0.10195246
A11: 7 | B11: =POISSON($A11,Model!B$16,TRUE()) -> 0.99977097 | C11: =POISSON($A11,Model!C$16,TRUE()) -> 0.99998357 | D11: =POISSON($A11,Model!D$16,TRUE()) -> 0.72254114 | E11: =POISSON($A11,Model!E$16,TRUE()) -> 0.026800495 | H11: =POISSON($A11,Model!$C$46,TRUE()) -> 0.98634679 | I11: =POISSON($A11,Model!$C$47,TRUE()) -> 0.72254114 | J11: =POISSON($A11,Model!$C$48,TRUE()) -> 0.076898979 | K11: =POISSON($A11,Model!$C$53,TRUE()) -> 0.98449866 | L11: =POISSON($A11,Model!$C$54,TRUE()) -> 0.47026869 | M11: =POISSON($A11,Model!$C$55,TRUE()) -> 0.026800495 | N11: =POISSON($A11,Model!$G$53,TRUE()) -> 0.98936414 | O11: =POISSON($A11,Model!$G$54,TRUE()) -> 0.65395161 | P11: =POISSON($A11,Model!$G$55,TRUE()) -> 0.17899037
A12: 8 | B12: =POISSON($A12,Model!B$16,TRUE()) -> 0.99996085 | C12: =POISSON($A12,Model!C$16,TRUE()) -> 0.99999807 | D12: =POISSON($A12,Model!D$16,TRUE()) -> 0.83095159 | E12: =POISSON($A12,Model!E$16,TRUE()) -> 0.053534035 | H12: =POISSON($A12,Model!$C$46,TRUE()) -> 0.9955327 | I12: =POISSON($A12,Model!$C$47,TRUE()) -> 0.83095159 | J12: =POISSON($A12,Model!$C$48,TRUE()) -> 0.13588236 | K12: =POISSON($A12,Model!$C$53,TRUE()) -> 0.99481321 | L12: =POISSON($A12,Model!$C$54,TRUE()) -> 0.60972176 | M12: =POISSON($A12,Model!$C$55,TRUE()) -> 0.053534035 | N12: =POISSON($A12,Model!$G$53,TRUE()) -> 0.99666797 | O12: =POISSON($A12,Model!$G$54,TRUE()) -> 0.77614232 | P12: =POISSON($A12,Model!$G$55,TRUE()) -> 0.28004259
A13: 9 | B13: =POISSON($A13,Model!B$16,TRUE()) -> 0.99999395 | C13: =POISSON($A13,Model!C$16,TRUE()) -> 0.9999998 | D13: =POISSON($A13,Model!D$16,TRUE()) -> 0.90507839 | E13: =POISSON($A13,Model!E$16,TRUE()) -> 0.096006005 | H13: =POISSON($A13,Model!$C$46,TRUE()) -> 0.99867318 | I13: =POISSON($A13,Model!$C$47,TRUE()) -> 0.90507839 | J13: =POISSON($A13,Model!$C$48,TRUE()) -> 0.21654339 | K13: =POISSON($A13,Model!$C$53,TRUE()) -> 0.99842419 | L13: =POISSON($A13,Model!$C$54,TRUE()) -> 0.731773 | M13: =POISSON($A13,Model!$C$55,TRUE()) -> 0.096006005 | N13: =POISSON($A13,Model!$G$53,TRUE()) -> 0.99905292 | O13: =POISSON($A13,Model!$G$54,TRUE()) -> 0.86612938 | P13: =POISSON($A13,Model!$G$55,TRUE()) -> 0.39786684
A14: 10 | B14: =POISSON($A14,Model!B$16,TRUE()) -> 0.99999915 | C14: =POISSON($A14,Model!C$16,TRUE()) -> 0.99999998 | D14: =POISSON($A14,Model!D$16,TRUE()) -> 0.95069488 | E14: =POISSON($A14,Model!E$16,TRUE()) -> 0.15673427 | H14: =POISSON($A14,Model!$C$46,TRUE()) -> 0.99963948 | I14: =POISSON($A14,Model!$C$47,TRUE()) -> 0.95069488 | J14: =POISSON($A14,Model!$C$48,TRUE()) -> 0.31581851 | K14: =POISSON($A14,Model!$C$53,TRUE()) -> 0.99956193 | L14: =POISSON($A14,Model!$C$54,TRUE()) -> 0.82791181 | M14: =POISSON($A14,Model!$C$55,TRUE()) -> 0.15673427 | N14: =POISSON($A14,Model!$G$53,TRUE()) -> 0.99975382 | O14: =POISSON($A14,Model!$G$54,TRUE()) -> 0.92577306 | P14: =POISSON($A14,Model!$G$55,TRUE()) -> 0.52150886
A15: 11 | B15: =POISSON($A15,Model!B$16,TRUE()) -> 0.99999989 | C15: =POISSON($A15,Model!C$16,TRUE()) -> 1 | D15: =POISSON($A15,Model!D$16,TRUE()) -> 0.97621459 | E15: =POISSON($A15,Model!E$16,TRUE()) -> 0.23567236 | H15: =POISSON($A15,Model!$C$46,TRUE()) -> 0.99990977 | I15: =POISSON($A15,Model!$C$47,TRUE()) -> 0.97621459 | J15: =POISSON($A15,Model!$C$48,TRUE()) -> 0.42689557 | K15: =POISSON($A15,Model!$C$53,TRUE()) -> 0.99988781 | L15: =POISSON($A15,Model!$C$54,TRUE()) -> 0.89675528 | M15: =POISSON($A15,Model!$C$55,TRUE()) -> 0.23567236 | N15: =POISSON($A15,Model!$G$53,TRUE()) -> 0.99994108 | O15: =POISSON($A15,Model!$G$54,TRUE()) -> 0.96171124 | P15: =POISSON($A15,Model!$G$55,TRUE()) -> 0.6394607
... A204: 200 | B204: =POISSON($A204,Model!B$16,TRUE()) -> 1 | C204: =POISSON($A204,Model!C$16,TRUE()) -> 1 | D204: =POISSON($A204,Model!D$16,TRUE()) -> 1 | E204: =POISSON($A204,Model!E$16,TRUE()) -> 1 | H204: =POISSON($A204,Model!$C$46,TRUE()) -> 1 | I204: =POISSON($A204,Model!$C$47,TRUE()) -> 1 | J204: =POISSON($A204,Model!$C$48,TRUE()) -> 1 | K204: =POISSON($A204,Model!$C$53,TRUE()) -> 1 | L204: =POISSON($A204,Model!$C$54,TRUE()) -> 1 | M204: =POISSON($A204,Model!$C$55,TRUE()) -> 1 | N204: =POISSON($A204,Model!$G$53,TRUE()) -> 1 | O204: =POISSON($A204,Model!$G$54,TRUE()) -> 1 | P204: =POISSON($A204,Model!$G$55,TRUE()) -> 1

Sheet Assumptions
A1: Assumption and source log - every number in the model
A3: Part class | B3: Parameter | C3: Current value | D3: Status | E3: Source / basis | F3: Replaced in
A4: Drives (HDD) | B4: Fleet size | C4: =Model!B6 -> 500 | D4: ASSUMPTION - illustrative | E4: Roadmap worked example (500 drives). | F4: User scenario input
A5: Drives (HDD) | B5: Annual failure rate | C5: =Model!B7 -> 0.0136 | D5: SOURCED - Backblaze | E5: Backblaze, 'Backblaze Drive Stats for 2025' - full-year 2025 fleet AFR 1.36% (2024: 1.55%). https://www.backblaze.com/blog/backblaze-drive-stats-for-2025/ | F5: -
A6: Drives (HDD) | B6: Lead time (weeks) | C6: =Model!B8 -> 12 | D6: ASSUMPTION - sample value | E6: Roadmap worked example (12 weeks). No supplier quote. | F6: Supplier quote later
A7: Drives (HDD) | B7: Target fill rate | C7: =Model!B9 -> 0.95 | D7: POLICY CHOICE | E7: Planner-set service target, not a measured value. | F7: User scenario input
A8: Drives (HDD) | B8: Unit cost ($) | C8: =Model!B10 -> 1079.99 | D8: SOURCED - tracked retail price | E8: ListofDisks product page, Seagate Exos ST24000NM002H 24TB (new): lowest current new offer $1,079.99 (Newegg), checked 2026-09-24. https://www.listofdisks.com/products/seagate-exos-24tb-st24000nm002h-d62767 . NOTE: user-supplied $559.99 was not found on ListofDisks for this drive on 2026-09-24. | F8: Re-check before quoting
A9: PSUs | B9: Fleet size | C9: =Model!C6 -> 400 | D9: ASSUMPTION - illustrative | E9: Illustrative fleet, not from a real site. | F9: User scenario input
A10: PSUs | B10: Datasheet MTBF (hours) | C10: =Model!C11 -> 500000 | D10: SOURCED - vendor datasheet | E10: Artesyn/Advanced Energy datasheet 'ARTESYN CSU SERIES 1800W to 2400W' (CRPS server PSU; covers CSU2000AP-3-100/-200): 'MTBF 500 k hours at 50 C, 85% load, nominal input'. https://www.mouser.com/datasheet/2/863/ENG_CSU_SERIES_235_01_06_03_25-3462455.pdf | F10: -
A11: PSUs | B11: Annual failure rate | C11: =Model!C7 -> 0.017367417 | D11: DERIVED | E11: AFR = 1 - e^(-8760 / MTBF). Assumes constant failure rate (exponential). Datasheet MTBF is quoted at 50 C / 85% load; field rates can differ. | F11: -
A12: PSUs | B12: Lead time (weeks) | C12: =Model!C8 -> 8 | D12: ASSUMPTION - placeholder | E12: No source yet. | F12: Supplier quote later
A13: PSUs | B13: Target fill rate | C13: =Model!C9 -> 0.95 | D13: POLICY CHOICE | E13: Planner-set service target. | F13: User scenario input
A14: PSUs | B14: Unit cost ($) | C14: =Model!C10 -> 531.16 | D14: SOURCED - distributor price | E14: Mouser, Advanced Energy/Artesyn CSU2000AP-3-100, qty-1 unit price $531.16, checked 2026-09-24. https://www.mouser.com/ProductDetail/Advanced-Energy-Artesyn/CSU2000AP-3-100?qs=PqoDHHvF649qddCp7yZ1ZA%3D%3D (DigiKey qty-1: $537.45) | F14: Re-check before quoting
A15: Optics (transceivers) | B15: Fleet size | C15: =Model!D6 -> 1000 | D15: ASSUMPTION - illustrative | E15: Illustrative fleet, not from a real site. | F15: User scenario input
A16: Optics (transceivers) | B16: Annual failure rate | C16: =Model!D7 -> 0.02 | D16: ASSUMPTION - unsourced | E16: No public field AFR for 800G optics found (searched vendor datasheets + literature, 2026-09-24). Planner assumption used as a sensitivity lever. Best lead: Xie et al., 'Characteristics of Field Operation Data for Optical Transceivers in Hyperscale Data Centers', OFC 2022 (IEEE paywall; abstract gives no rate). | F16: Tested at 1% / 2% / 4% (Model rows 46-48)
A17: Optics (transceivers) | B17: Lead time (weeks) | C17: =Model!D8 -> 16 | D17: ASSUMPTION - placeholder | E17: No source yet. | F17: Supplier quote later
A18: Optics (transceivers) | B18: Target fill rate | C18: =Model!D9 -> 0.95 | D18: POLICY CHOICE | E18: Planner-set service target. | F18: User scenario input
A19: Optics (transceivers) | B19: Unit cost ($) - selected scenario | C19: =Model!D10 -> 919 | D19: FORMULA | E19: Follows the Generic/Branded toggle in Model!I6. | F19: -
A20: Optics (transceivers) | B20: Generic price ($) | C20: =Model!I7 -> 919 | D20: SOURCED - vendor list price | E20: NADDOD #32798, Generic Compatible 800GBASE-2xXDR4 OSFP (OSFP-800G-2xXDR4), US$919.00, checked live 2026-09-24. https://www.naddod.com/products/32798.html . NOTE: user-supplied $1,199 did not appear on the page on 2026-09-24. | F20: Re-check before quoting
A21: Optics (transceivers) | B21: Branded-equivalent price ($) | C21: =Model!I8 -> 4141.54 | D21: SOURCED - reseller MSRP | E21: SHI, Axiom OSFP112 transceiver (equivalent to Arista OSFP-800G-2XDR4), MSRP $4,141.54 (SHI selling price shown: $3,795.00), checked 2026-09-24. https://www.shi.com/product/50875021/Axiom-OSFP112-transceiver-module-(equivalent-to:-Arista-OSFP-800G-2XDR4) | F21: Re-check before quoting
A22: GPUs (H100) | B22: GPUs installed | C22: =Model!I16 -> 1024 | D22: ASSUMPTION - sample value | E22: 1,024 GPUs = 128 HGX boards. Illustrative cluster, not from a real site. | F22: User scenario input
A23: GPUs (H100) | B23: Sparing unit | C23: =Model!I17 -> Module | D23: POLICY CHOICE | E23: Module = spare single SXM GPUs; Board = spare whole 8-GPU HGX boards. Both shown side by side in Model rows 51-56. | F23: User scenario input
A24: GPUs (H100) | B24: Llama 3 interruption counts / cluster / days | C24: =Model!I20+Model!I21 -> 220 | D24: SOURCED - Meta paper | E24: Meta, 'The Llama 3 Herd of Models' (2024), Table 5: 54-day pre-training run on 16,384 H100 80GB GPUs; 419 unexpected interruptions, incl. 148 faulty GPU (30.1%) and 72 GPU HBM3 memory (17.2%). https://ai.meta.com/research/publications/the-llama-3-herd-of-models/ (summary: https://www.datacenterdynamics.com/en/news/meta-report-details-hundreds-of-gpu-and-hbm3-related-interruptions-to-llama-3-training-run/) | F24: -
A25: GPUs (H100) | B25: Per-GPU AFR | C25: =Model!I24 -> 0.090761538 | D25: DERIVED - upper bound | E25: (148 + 72) / 16,384 x 365 / 54 = 9.08%. This is an interruption rate from one training run, not a confirmed replacement rate; some faults clear with a reset. Tested at 2% / 5% / 9.08% (Model rows 53-55). | F25: Sensitivity rows 53-55
A26: GPUs (H100) | B26: HGX board price ($) | C26: =Model!I19 -> 179000 | D26: SOURCED - reseller list price | E26: Network Outlet, 'NVIDIA HGX H100 SXM5 8-GPU Board (935-24287-0301-000) Board - New', $179,000.00, checked 2026-09-25. https://networkoutlet.com/products/nvidia-hgx-h100-sxm5-8-gpu-board-935-24287-0301-000-board-new | F26: Re-check before quoting
A27: GPUs (H100) | B27: Module unit cost ($) | C27: =Model!I19/Model!I18 -> 22375 | D27: DERIVED - proxy | E27: Board price / 8 = $22,375. Proxy only: single H100 SXM modules are rarely sold new on their own. | F27: -
A28: GPUs (H100) | B28: Lead time (weeks) | C28: =Model!E8 -> 8 | D28: ASSUMPTION - placeholder | E28: No source yet - sample value. | F28: Supplier quote later
A29: GPUs (H100) | B29: Target fill rate | C29: =Model!E9 -> 0.95 | D29: POLICY CHOICE | E29: Planner-set service target. | F29: User scenario input
A30: All | B30: Weeks per year | C30: =Model!B12 -> 52 | D30: CONSTANT | E30: Calendar convention. | F30: -
A31: All | B31: Hours per year | C31: =Model!B13 -> 8760 | D31: CONSTANT | E31: 365 x 24. | F31: -

Sheet Check
A1: Worked example verification (self-contained - does not depend on Model inputs)
A3: Inputs
A4: Fleet size | B4: 500 | C4: Source: roadmap Step 2 spec
A5: Annual failure rate (Backblaze 2025) | B5: 0.0136
A6: Lead time (weeks) | B6: 12
A7: Weeks per year | B7: 52
A8: Target fill rate | B8: 0.95
A10: Check | B10: Model logic result | C10: Expected (spec / hand calc) | D10: Tolerance | E10: Result
A11: Expected failures per year | B11: =B4*B5 -> 6.8 | C11: 6.8 | D11: 0.001 | E11: =IF(ABS(B11-C11)<=D11,"PASS","FAIL") -> PASS
A12: Expected demand during lead time | B12: =B11*B6/B7 -> 1.5692308 | C12: 1.57 | D12: 0.01 | E12: =IF(ABS(B12-C12)<=D12,"PASS","FAIL") -> PASS
A13: Poisson S at 95% fill rate (hand calc: P(D<=3)=0.926, P(D<=4)=0.979, so S-1=4) | B13: =IF(POISSON(3,B12,TRUE())>=B8,4,IF(POISSON(4,B12,TRUE())>=B8,5,99)) -> 5 | C13: 5 | D13: 0 | E13: =IF(ABS(B13-C13)<=D13,"PASS","FAIL") -> PASS
A14: Model tab reproduces this S when drive inputs = example | B14: =IF(AND(Model!B6=B4,Model!B7=B5,Model!B8=B6,Model!B9=B8),Model!B17,B13) -> 5 | C14: 5 | D14: 0 | E14: =IF(ABS(B14-C14)<=D14,"PASS","FAIL") -> PASS
A15: PSU AFR from 500k-hour MTBF: 1 - e^(-8760/500000) | B15: =1-EXP(-8760/500000) -> 0.017367417 | C15: 0.01737 | D15: 1e-05 | E15: =IF(ABS(B15-C15)<=D15,"PASS","FAIL") -> PASS
A19: Row 13: fill rate = P(D <= S-1). P(D<=3) = 92.6% misses 95%, P(D<=4) = 97.9% clears it, so S-1 = 4 and S = 5.
A20: Row 14 reads the Model only while its drive inputs match the example; otherwise it echoes row 13 so scenario changes don't break the check.
A22: RESUME NUMBERS CHECK (base-case Model inputs) | B22: Model result | C22: Expected (hand calc) | D22: Tolerance | E22: Result
A23: Drive stock at 95% fill rate, P(D<=S-1) | B23: =Model!B17 -> 5 | C23: 5 | D23: 0 | E23: =IF(ABS(B23-C23)<=D23,"PASS","FAIL") -> PASS
A24: Drive stock at 95% cycle service level, P(D<=S) | B24: =COUNTIF(Poisson_Table!B4:B204,"<"&Model!B9) -> 4 | C24: 4 | D24: 0 | E24: =IF(ABS(B24-C24)<=D24,"PASS","FAIL") -> PASS
A25: Extra optics units: normal approx minus Poisson | B25: =Model!D27-Model!D17 -> 1 | C25: 1 | D25: 0 | E25: =IF(ABS(B25-C25)<=D25,"PASS","FAIL") -> PASS
A26: Drive + optics spares capital, generic optics (5 x $1,079.99 + 11 x $919.00) | B26: =Model!B41 -> 15508.95 | C26: 15508.95 | D26: 0.01 | E26: =IF(ABS(B26-C26)<=D26,"PASS","FAIL") -> PASS
A27: Drive + optics spares capital, branded optics (5 x $1,079.99 + 11 x $4,141.54) | B27: =Model!C41 -> 50956.89 | C27: 50956.89 | D27: 0.01 | E27: =IF(ABS(B27-C27)<=D27,"PASS","FAIL") -> PASS
A28: The earlier ~$16,000 target assumed $559.99 drives and $1,199 optics. Neither price was on the linked pages on 2026-09-24; rows 26-27 use the verified prices.
A29: Rows 23-27 assume base-case Model inputs; they will FAIL by design if you change the scenario.
A31: GPU CHECKS (base case, I17 = Module) | B31: Model result | C31: Expected (hand calc) | D31: Tolerance | E31: Result
A32: Per-GPU AFR = (148+72)/16,384 x 365/54 | B32: =Model!I24 -> 0.090761538 | C32: 0.090762 | D32: 1e-06 | E32: =IF(ABS(B32-C32)<=D32,"PASS","FAIL") -> PASS
A33: Board AFR = 1-(1-AFR)^8 | B33: =Model!F55 -> 0.53288653 | C33: 0.532887 | D33: 1e-06 | E33: =IF(ABS(B33-C33)<=D33,"PASS","FAIL") -> PASS
A34: Module stock S at 95% fill rate | B34: =Model!D55 -> 22 | C34: 22 | D34: 0 | E34: =IF(ABS(B34-C34)<=D34,"PASS","FAIL") -> PASS
A35: Module spares capital (22 x $22,375) | B35: =Model!E55 -> 492250 | C35: 492250 | D35: 0.01 | E35: =IF(ABS(B35-C35)<=D35,"PASS","FAIL") -> PASS
A36: Board stock S at 95% fill rate | B36: =Model!H55 -> 17 | C36: 17 | D36: 0 | E36: =IF(ABS(B36-C36)<=D36,"PASS","FAIL") -> PASS
A37: Board spares capital (17 x $179,000) | B37: =Model!I55 -> 3043000 | C37: 3043000 | D37: 0.01 | E37: =IF(ABS(B37-C37)<=D37,"PASS","FAIL") -> PASS
A38: Model column E (Module) stock S | B38: =Model!E17 -> 22 | C38: 22 | D38: 0 | E38: =IF(ABS(B38-C38)<=D38,"PASS","FAIL") -> PASS
A39: All-4-classes capital, generic optics, GPU module | B39: =Model!B42 -> 509883.59 | C39: 509883.59 | D39: 0.01 | E39: =IF(ABS(B39-C39)<=D39,"PASS","FAIL") -> PASS
A40: All-4-classes capital, branded optics, GPU module | B40: =Model!C42 -> 545331.53 | C40: 545331.53 | D40: 0.01 | E40: =IF(ABS(B40-C40)<=D40,"PASS","FAIL") -> PASS
A42: Overall | E42: =IF(COUNTIF(E11:E15,"PASS")+COUNTIF(E23:E27,"PASS")+COUNTIF(E32:E40,"PASS")=19,"ALL PASS","CHECK FAILED") -> ALL PASS
